 <link name="link_1">
    <visual>
      <geometry>
        <cylinder length="0.5" radius="0.03"/>
        </geometry>
          <origin xyz="0.165 0.25 0.23" rpy="0 0.6 0.6"/>
     </visual>
    </link>

    <link name="link_2">
     <visual>
        <geometry>
          <cylinder length="0.55" radius="0.03"/>
            </geometry>
      <origin xyz="0.24 0.25 0.46" rpy="0 0.4 0"/>
       </visual>
</link>
    
  
    <joint name="Revolute_joint_1" type="revolute">
    <parent link="fixed_base"/>
      <child link="link_1"/>
      <origin xyz="0 -0.25 0"/>
        </joint>
    <joint name="Revolute_joint_2" type="revolute">
       <parent link="link_1"/>
      <child link="link_2"/>
      <origin xyz="0.17 0 0.22"/>
      </joint>
      </robot>
